Workbook

Sheet Dashboard
A1: KLARAVEX — Executive Dashboard
A3: Active scenario | B3: =CHOOSE(Drivers!$B$43,"Conservative","Base","Aggressive")
A5: NORTH STAR — AI deflection rate | B5: =Drivers!$E$51 | C5: Target ≥75%. Drives cost-to-serve.
A6: M12 MRR | B6: =Projection!$M$10 | C6: Monthly recurring at month 12.
A7: Net new MRR (M12 vs M1) | B7: =Projection!$M$10-Projection!$B$10 | C7: MRR added across the year.
A8: ARR run-rate (M12 x 12) | B8: =Projection!$M$10*12 | C8: Annualized exit run-rate.
A9: Gross margin % (M12) | B9: =Projection!$M$15 | C9: Revenue minus cost-to-serve.
A10: LTV:CAC — B2B | B10: =UnitEconomics!B21/UnitEconomics!B22 | C10: Healthy >3x.
A11: LTV:CAC — B2C | B11: =UnitEconomics!C21/UnitEconomics!C22 | C11: Healthy >3x.
A12: Breakeven month | B12: =Projection!$B$22 | C12: First month contribution>0.
A13: Ending cash (M12) | B13: =Projection!$M$19 | C13: Cumulative cash at year end.
A14: Runway note | B14: =IF(Projection!$M$18>0,"Cash-flow positive","Burning - watch runway") | C14: Status at M12.

Sheet Drivers
A1: KLARAVEX — Assumptions & Drivers (yellow = editable input)
A2: Every yellow cell is an input. Change it and the whole model recalculates.
A4: AI / COST-TO-SERVE DRIVERS
A5: AI cost per ticket (B2B) | B5: 0.35
A6: AI cost per session (B2C) | B6: 0.8
A7: AI deflection rate (base) — NORTH STAR | B7: 0.75
A8: Human escalation rate | B8: =1-B6
A9: Senior engineer cost / hr | B9: 60
A10: Human hours per escalation | B10: 0.5
A11: Tooling fixed cost / mo | B11: 1500
A13: RETENTION / CHURN & PROCESSING
A14: Monthly churn — B2B | B14: 0.03
A15: Monthly churn — B2C | B15: 0.06
A16: Payment processing % | B16: 0.03
A17: FX rate EUR -> USD | B17: 1.08
A19: PRICING (per tier)
A20: B2B Managed — price / seat / mo | B20: 49
A21: B2B Managed — monthly floor | B21: 245
A22: B2B avg seats per account | B22: 8
A23: B2C Family — price / mo | B23: 79
A24: B2C one-time setup fee | B24: 99
A25: % of new B2C taking setup | B25: 0.6
A27: ARPU (derived monthly recurring per customer)
A28: ARPU — B2B account / mo | B28: =MAX(Drivers!$B$21,Drivers!$B$20*Drivers!$B$22)
A29: ARPU — B2C member / mo | B29: =Drivers!$B$23
A31: CAC BY CHANNEL
A32: CAC — B2B (outbound/partner) | B32: 850
A33: CAC — B2C (paid social) | B33: 65
A35: USAGE INTENSITY (drives variable cost)
A36: Tickets per B2B account / mo | B36: 40
A37: Sessions per B2C member / mo | B37: 6
A38: Other fixed opex / mo (G&A) | B38: 6000
A39: Starting cash balance | B39: 150000
A40: Ad spend / mo (S&M, growth) | B40: 8000
A42: SCENARIO TOGGLE (1=Conservative, 2=Base, 3=Aggressive)
A43: Active scenario | B43: 2
A44: Active scenario name | B44: =CHOOSE(Drivers!$B$43,"Conservative","Base","Aggressive")
A46: Scenario drivers | B46: Conservative | C46: Base | D46: Aggressive | E46: ACTIVE
A47: New B2C members / mo (M1) | B47: 60 | C47: 120 | D47: 220 | E47: =CHOOSE(Drivers!$B$43,B47,C47,D47)
A48: B2C monthly growth rate | B48: 0.08 | C48: 0.15 | D48: 0.25 | E48: =CHOOSE(Drivers!$B$43,B48,C48,D48)
...

Sheet UnitEconomics
A1: KLARAVEX — Unit Economics (live formulas)
A3: VARIABLE COST TO SERVE
A4: Cost per AI ticket (B2B) | B4: =Drivers!$B$5
A5: Cost per human escalation (B2B) | B5: =(1-Drivers!$E$51)*Drivers!$B$9*Drivers!$B$10
A6: Blended var cost / B2B ticket | B6: =Drivers!$E$51*Drivers!$B$5+(1-Drivers!$E$51)*Drivers!$B$9*Drivers!$B$10
A7: Var cost / B2B account / mo | B7: =UnitEconomics!$B$6*Drivers!$B$36
A8: Cost per AI session (B2C) | B8: =Drivers!$B$6
A9: Blended var cost / B2C session | B9: =Drivers!$E$51*Drivers!$B$6+(1-Drivers!$E$51)*Drivers!$B$9*Drivers!$B$10
A10: Var cost / B2C member / mo | B10: =UnitEconomics!$B$9*Drivers!$B$37
A12: GROSS MARGIN PER OFFERING
A13: ARPU | B13: B2B account | C13: B2C member
A14: ARPU / mo | B14: =Drivers!$B$28 | C14: =Drivers!$B$29
A15: Processing cost / mo | B15: =B14*Drivers!$B$16 | C15: =C14*Drivers!$B$16
A16: Var cost to serve / mo | B16: =UnitEconomics!$B$7 | C16: =UnitEconomics!$B$10
A17: Gross profit / mo | B17: =B14-B14*Drivers!$B$16-UnitEconomics!$B$7 | C17: =C14-C14*Drivers!$B$16-UnitEconomics!$B$10
A18: Gross margin % | B18: =B17/B14 | C18: =C17/C14
A20: LTV / CAC / PAYBACK
A21: Avg customer lifetime (mo) = 1/churn | B21: =1/Drivers!$B$14 | C21: =1/Drivers!$B$15
A22: LTV (gross profit * lifetime) | B22: =B17*B21 | C22: =C17*C21
A23: CAC (scenario-adjusted) | B23: =Drivers!$B$32*Drivers!$E$52 | C23: =Drivers!$B$33*Drivers!$E$52
A24: LTV : CAC | B24: =B22/B23 | C24: =C22/C23
A25: Payback (months) | B25: =B23/B17 | C25: =C23/C17

Sheet Projection
A1: KLARAVEX — 12-Month P&L / Projection (driver-linked, scenario-aware)
A3: Line item ($) | B3: M1 | C3: M2 | D3: M3 | E3: M4 | F3: M5 | G3: M6 | H3: M7 | I3: M8 | J3: M9 | K3: M10 | L3: M11 | M3: M12
A4: New B2C members | B4: =Drivers!$E$47 | C4: =B4*(1+Drivers!$E$48) | D4: =C4*(1+Drivers!$E$48) | E4: =D4*(1+Drivers!$E$48) | F4: =E4*(1+Drivers!$E$48) | G4: =F4*(1+Drivers!$E$48) | H4: =G4*(1+Drivers!$E$48) | I4: =H4*(1+Drivers!$E$48) | J4: =I4*(1+Drivers!$E$48) | ... M4: =L4*(1+Drivers!$E$48)
A5: New B2B accounts | B5: =Drivers!$E$49 | C5: =B5*(1+Drivers!$E$50) | D5: =C5*(1+Drivers!$E$50) | E5: =D5*(1+Drivers!$E$50) | F5: =E5*(1+Drivers!$E$50) | G5: =F5*(1+Drivers!$E$50) | H5: =G5*(1+Drivers!$E$50) | I5: =H5*(1+Drivers!$E$50) | J5: =I5*(1+Drivers!$E$50) | ... M5: =L5*(1+Drivers!$E$50)
A6: Active B2C members | B6: =B4 | C6: =B6*(1-Drivers!$B$15)+C4 | D6: =C6*(1-Drivers!$B$15)+D4 | E6: =D6*(1-Drivers!$B$15)+E4 | F6: =E6*(1-Drivers!$B$15)+F4 | G6: =F6*(1-Drivers!$B$15)+G4 | H6: =G6*(1-Drivers!$B$15)+H4 | I6: =H6*(1-Drivers!$B$15)+I4 | J6: =I6*(1-Drivers!$B$15)+J4 | ... M6: =L6*(1-Drivers!$B$15)+M4
A7: Active B2B accounts | B7: =B5 | C7: =B7*(1-Drivers!$B$14)+C5 | D7: =C7*(1-Drivers!$B$14)+D5 | E7: =D7*(1-Drivers!$B$14)+E5 | F7: =E7*(1-Drivers!$B$14)+F5 | G7: =F7*(1-Drivers!$B$14)+G5 | H7: =G7*(1-Drivers!$B$14)+H5 | I7: =H7*(1-Drivers!$B$14)+I5 | J7: =I7*(1-Drivers!$B$14)+J5 | ... M7: =L7*(1-Drivers!$B$14)+M5
A8: MRR — B2C | B8: =B6*Drivers!$B$29 | C8: =C6*Drivers!$B$29 | D8: =D6*Drivers!$B$29 | E8: =E6*Drivers!$B$29 | F8: =F6*Drivers!$B$29 | G8: =G6*Drivers!$B$29 | H8: =H6*Drivers!$B$29 | I8: =I6*Drivers!$B$29 | ... M8: =M6*Drivers!$B$29
A9: MRR — B2B | B9: =B7*Drivers!$B$28 | C9: =C7*Drivers!$B$28 | D9: =D7*Drivers!$B$28 | E9: =E7*Drivers!$B$28 | F9: =F7*Drivers!$B$28 | G9: =G7*Drivers!$B$28 | H9: =H7*Drivers!$B$28 | I9: =I7*Drivers!$B$28 | ... M9: =M7*Drivers!$B$28
A10: Total MRR | B10: =B8+B9 | C10: =C8+C9 | D10: =D8+D9 | E10: =E8+E9 | F10: =F8+F9 | G10: =G8+G9 | H10: =H8+H9 | I10: =I8+I9 | ... M10: =M8+M9
A11: One-time revenue (setup) | B11: =B4*Drivers!$B$25*Drivers!$B$24 | C11: =C4*Drivers!$B$25*Drivers!$B$24 | D11: =D4*Drivers!$B$25*Drivers!$B$24 | E11: =E4*Drivers!$B$25*Drivers!$B$24 | F11: =F4*Drivers!$B$25*Drivers!$B$24 | G11: =G4*Drivers!$B$25*Drivers!$B$24 | H11: =H4*Drivers!$B$25*Drivers!$B$24 | I11: =I4*Drivers!$B$25*Drivers!$B$24 | ... M11: =M4*Drivers!$B$25*Drivers!$B$24
A12: TOTAL REVENUE | B12: =B10+B11 | C12: =C10+C11 | D12: =D10+D11 | E12: =E10+E11 | F12: =F10+F11 | G12: =G10+G11 | H12: =H10+H11 | I12: =I10+I11 | ... M12: =M10+M11
A13: COGS (var cost + processing) | B13: =B6*UnitEconomics!$B$10+B7*UnitEconomics!$B$7+B12*Drivers!$B$16 | C13: =C6*UnitEconomics!$B$10+C7*UnitEconomics!$B$7+C12*Drivers!$B$16 | D13: =D6*UnitEconomics!$B$10+D7*UnitEconomics!$B$7+D12*Drivers!$B$16 | E13: =E6*UnitEconomics!$B$10+E7*UnitEconomics!$B$7+E12*Drivers!$B$16 | F13: =F6*UnitEconomics!$B$10+F7*UnitEconomics!$B$7+F12*Drivers!$B$16 | G13: =G6*UnitEconomics!$B$10+G7*UnitEconomics!$B$7+G12*Drivers!$B$16 | H13: =H6*UnitEconomics!$B$10+H7*UnitEconomics!$B$7+H12*Drivers!$B$16 | I13: =I6*UnitEconomics!$B$10+I7*UnitEconomics!$B$7+I12*Drivers!$B$16 | ... M13: =M6*UnitEconomics!$B$10+M7*UnitEconomics!$B$7+M12*Drivers!$B$16
A14: Gross margin $ | B14: =B12-B13 | C14: =C12-C13 | D14: =D12-D13 | E14: =E12-E13 | F14: =F12-F13 | G14: =G12-G13 | H14: =H12-H13 | I14: =I12-I13 | ... M14: =M12-M13
A15: Gross margin % | B15: =B14/B12 | C15: =C14/C12 | D15: =D14/D12 | E15: =E14/E12 | F15: =F14/F12 | G15: =G14/G12 | H15: =H14/H12 | I15: =I14/I12 | ... M15: =M14/M12
A16: Acquisition cost (CAC) | B16: =B4*Drivers!$B$33*Drivers!$E$52+B5*Drivers!$B$32*Drivers!$E$52 | C16: =C4*Drivers!$B$33*Drivers!$E$52+C5*Drivers!$B$32*Drivers!$E$52 | D16: =D4*Drivers!$B$33*Drivers!$E$52+D5*Drivers!$B$32*Drivers!$E$52 | E16: =E4*Drivers!$B$33*Drivers!$E$52+E5*Drivers!$B$32*Drivers!$E$52 | F16: =F4*Drivers!$B$33*Drivers!$E$52+F5*Drivers!$B$32*Drivers!$E$52 | G16: =G4*Drivers!$B$33*Drivers!$E$52+G5*Drivers!$B$32*Drivers!$E$52 | H16: =H4*Drivers!$B$33*Drivers!$E$52+H5*Drivers!$B$32*Drivers!$E$52 | I16: =I4*Drivers!$B$33*Drivers!$E$52+I5*Drivers!$B$32*Drivers!$E$52 | ... M16: =M4*Drivers!$B$33*Drivers!$E$52+M5*Drivers!$B$32*Drivers!$E$52
A17: Fixed opex (tooling+G&A+ads) | B17: =Drivers!$B$11+Drivers!$B$38+Drivers!$B$40 | C17: =Drivers!$B$11+Drivers!$B$38+Drivers!$B$40 | D17: =Drivers!$B$11+Drivers!$B$38+Drivers!$B$40 | E17: =Drivers!$B$11+Drivers!$B$38+Drivers!$B$40 | F17: =Drivers!$B$11+Drivers!$B$38+Drivers!$B$40 | G17: =Drivers!$B$11+Drivers!$B$38+Drivers!$B$40 | H17: =Drivers!$B$11+Drivers!$B$38+Drivers!$B$40 | I17: =Drivers!$B$11+Drivers!$B$38+Drivers!$B$40 | ... M17: =Drivers!$B$11+Drivers!$B$38+Drivers!$B$40
A18: Contribution / EBITDA | B18: =B14-B16-B17 | C18: =C14-C16-C17 | D18: =D14-D16-D17 | E18: =E14-E16-E17 | F18: =F14-F16-F17 | G18: =G14-G16-G17 | H18: =H14-H16-H17 | I18: =I14-I16-I17 | ... M18: =M14-M16-M17
A19: Cumulative cash | B19: =Drivers!$B$39+B18 | C19: =B19+C18 | D19: =C19+D18 | E19: =D19+E18 | F19: =E19+F18 | G19: =F19+G18 | H19: =G19+H18 | I19: =H19+I18 | J19: =I19+J18 | ... M19: =L19+M18
A20: Breakeven (contrib>0?) | B20: =IF(B18>0,"YES","no") | C20: =IF(C18>0,"YES","no") | D20: =IF(D18>0,"YES","no") | E20: =IF(E18>0,"YES","no") | F20: =IF(F18>0,"YES","no") | G20: =IF(G18>0,"YES","no") | H20: =IF(H18>0,"YES","no") | I20: =IF(I18>0,"YES","no") | ... M20: =IF(M18>0,"YES","no")
A22: First breakeven month | B22: =IFERROR("M"&MATCH("YES",B20:M20,0),"none in 12mo")

Sheet Scenarios
A1: KLARAVEX — Scenario Comparison (toggle on Drivers!B43 drives ACTIVE)
A3: Metric | B3: Conservative | C3: Base | D3: Aggressive | E3: ACTIVE
A4: Deflection rate (North Star) | B4: =Drivers!$B$51 | C4: =Drivers!$C$51 | D4: =Drivers!$D$51 | E4: =Drivers!$E$51
A5: M12 MRR | B5: =((Drivers!$B$47*(1+Drivers!$B$48)^0*(1-Drivers!$B$15)^11+Drivers!$B$47*(1+Drivers!$B$48)^1*(1-Drivers!$B$15)^10+Drivers!$B$47*(1+Drivers!$B$48)^2*(1-Drivers!$B$15)^9+Drivers!$B$47*(1+Drivers!$B$48)^3*(1-Drivers!$B$15)^8+Drivers!$B$47*(1+Drivers!$B$48)^4*(1-Drivers!$B$15)^7+Drivers!$B$47*(1+Drivers!$B$48)^5*(1-Drivers!$B$15)^6+Drivers!$B$47*(1+Drivers!$B$48)^6*(1-Drivers!$B$15)^5+Drivers!$B$47*(1+Drivers!$B$48)^7*(1-Drivers!$B$15)^4+Drivers!$B$47*(1+Drivers!$B$48)^8*(1-Drivers!$B$15)^3+Drivers!$B$47*(1+Drivers!$B$48)^9*(1-Drivers!$B$15)^2+Drivers!$B$47*(1+Drivers!$B$48)^10*(1-Drivers!$B$15)^1+Drivers!$B$47*(1+Drivers!$B$48)^11*(1-Drivers!$B$15)^0)*Drivers!$B$29+(Drivers!$B$49*(1+Drivers!$B$50)^0*(1-Drivers!$B$14)^11+Drivers!$B$49*(1+Drivers!$B$50)^1*(1-Drivers!$B$14)^10+Drivers!$B$49*(1+Drivers!$B$50)^2*(1-Drivers!$B$14)^9+Drivers!$B$49*(1+Drivers!$B$50)^3*(1-Drivers!$B$14)^8+Drivers!$B$49*(1+Drivers!$B$50)^4*(1-Drivers!$B$14)^7+Drivers!$B$49*(1+Drivers!$B$50)^5*(1-Drivers!$B$14)^6+Drivers!$B$49*(1+Drivers!$B$50)^6*(1-Drivers!$B$14)^5+Drivers!$B$49*(1+Drivers!$B$50)^7*(1-Drivers!$B$14)^4+Drivers!$B$49*(1+Drivers!$B$50)^8*(1-Drivers!$B$14)^3+Drivers!$B$49*(1+Drivers!$B$50)^9*(1-Drivers!$B$14)^2+Drivers!$B$49*(1+Drivers!$B$50)^10*(1-Drivers!$B$14)^1+Drivers!$B$49*(1+Drivers!$B$50)^11*(1-Drivers!$B$14)^0)*Drivers!$B$28) | C5: =((Drivers!$C$47*(1+Drivers!$C$48)^0*(1-Drivers!$B$15)^11+Drivers!$C$47*(1+Drivers!$C$48)^1*(1-Drivers!$B$15)^10+Drivers!$C$47*(1+Drivers!$C$48)^2*(1-Drivers!$B$15)^9+Drivers!$C$47*(1+Drivers!$C$48)^3*(1-Drivers!$B$15)^8+Drivers!$C$47*(1+Drivers!$C$48)^4*(1-Drivers!$B$15)^7+Drivers!$C$47*(1+Drivers!$C$48)^5*(1-Drivers!$B$15)^6+Drivers!$C$47*(1+Drivers!$C$48)^6*(1-Drivers!$B$15)^5+Drivers!$C$47*(1+Drivers!$C$48)^7*(1-Drivers!$B$15)^4+Drivers!$C$47*(1+Drivers!$C$48)^8*(1-Drivers!$B$15)^3+Drivers!$C$47*(1+Drivers!$C$48)^9*(1-Drivers!$B$15)^2+Drivers!$C$47*(1+Drivers!$C$48)^10*(1-Drivers!$B$15)^1+Drivers!$C$47*(1+Drivers!$C$48)^11*(1-Drivers!$B$15)^0)*Drivers!$B$29+(Drivers!$C$49*(1+Drivers!$C$50)^0*(1-Drivers!$B$14)^11+Drivers!$C$49*(1+Drivers!$C$50)^1*(1-Drivers!$B$14)^10+Drivers!$C$49*(1+Drivers!$C$50)^2*(1-Drivers!$B$14)^9+Drivers!$C$49*(1+Drivers!$C$50)^3*(1-Drivers!$B$14)^8+Drivers!$C$49*(1+Drivers!$C$50)^4*(1-Drivers!$B$14)^7+Drivers!$C$49*(1+Drivers!$C$50)^5*(1-Drivers!$B$14)^6+Drivers!$C$49*(1+Drivers!$C$50)^6*(1-Drivers!$B$14)^5+Drivers!$C$49*(1+Drivers!$C$50)^7*(1-Drivers!$B$14)^4+Drivers!$C$49*(1+Drivers!$C$50)^8*(1-Drivers!$B$14)^3+Drivers!$C$49*(1+Drivers!$C$50)^9*(1-Drivers!$B$14)^2+Drivers!$C$49*(1+Drivers!$C$50)^10*(1-Drivers!$B$14)^1+Drivers!$C$49*(1+Drivers!$C$50)^11*(1-Drivers!$B$14)^0)*Drivers!$B$28) | D5: =((Drivers!$D$47*(1+Drivers!$D$48)^0*(1-Drivers!$B$15)^11+Drivers!$D$47*(1+Drivers!$D$48)^1*(1-Drivers!$B$15)^10+Drivers!$D$47*(1+Drivers!$D$48)^2*(1-Drivers!$B$15)^9+Drivers!$D$47*(1+Drivers!$D$48)^3*(1-Drivers!$B$15)^8+Drivers!$D$47*(1+Drivers!$D$48)^4*(1-Drivers!$B$15)^7+Drivers!$D$47*(1+Drivers!$D$48)^5*(1-Drivers!$B$15)^6+Drivers!$D$47*(1+Drivers!$D$48)^6*(1-Drivers!$B$15)^5+Drivers!$D$47*(1+Drivers!$D$48)^7*(1-Drivers!$B$15)^4+Drivers!$D$47*(1+Drivers!$D$48)^8*(1-Drivers!$B$15)^3+Drivers!$D$47*(1+Drivers!$D$48)^9*(1-Drivers!$B$15)^2+Drivers!$D$47*(1+Drivers!$D$48)^10*(1-Drivers!$B$15)^1+Drivers!$D$47*(1+Drivers!$D$48)^11*(1-Drivers!$B$15)^0)*Drivers!$B$29+(Drivers!$D$49*(1+Drivers!$D$50)^0*(1-Drivers!$B$14)^11+Drivers!$D$49*(1+Drivers!$D$50)^1*(1-Drivers!$B$14)^10+Drivers!$D$49*(1+Drivers!$D$50)^2*(1-Drivers!$B$14)^9+Drivers!$D$49*(1+Drivers!$D$50)^3*(1-Drivers!$B$14)^8+Drivers!$D$49*(1+Drivers!$D$50)^4*(1-Drivers!$B$14)^7+Drivers!$D$49*(1+Drivers!$D$50)^5*(1-Drivers!$B$14)^6+Drivers!$D$49*(1+Drivers!$D$50)^6*(1-Drivers!$B$14)^5+Drivers!$D$49*(1+Drivers!$D$50)^7*(1-Drivers!$B$14)^4+Drivers!$D$49*(1+Drivers!$D$50)^8*(1-Drivers!$B$14)^3+Drivers!$D$49*(1+Drivers!$D$50)^9*(1-Drivers!$B$14)^2+Drivers!$D$49*(1+Drivers!$D$50)^10*(1-Drivers!$B$14)^1+Drivers!$D$49*(1+Drivers!$D$50)^11*(1-Drivers!$B$14)^0)*Drivers!$B$28) | E5: =Projection!$M$10
A6: M12 ARR run-rate | B6: =12*((Drivers!$B$47*(1+Drivers!$B$48)^0*(1-Drivers!$B$15)^11+Drivers!$B$47*(1+Drivers!$B$48)^1*(1-Drivers!$B$15)^10+Drivers!$B$47*(1+Drivers!$B$48)^2*(1-Drivers!$B$15)^9+Drivers!$B$47*(1+Drivers!$B$48)^3*(1-Drivers!$B$15)^8+Drivers!$B$47*(1+Drivers!$B$48)^4*(1-Drivers!$B$15)^7+Drivers!$B$47*(1+Drivers!$B$48)^5*(1-Drivers!$B$15)^6+Drivers!$B$47*(1+Drivers!$B$48)^6*(1-Drivers!$B$15)^5+Drivers!$B$47*(1+Drivers!$B$48)^7*(1-Drivers!$B$15)^4+Drivers!$B$47*(1+Drivers!$B$48)^8*(1-Drivers!$B$15)^3+Drivers!$B$47*(1+Drivers!$B$48)^9*(1-Drivers!$B$15)^2+Drivers!$B$47*(1+Drivers!$B$48)^10*(1-Drivers!$B$15)^1+Drivers!$B$47*(1+Drivers!$B$48)^11*(1-Drivers!$B$15)^0)*Drivers!$B$29+(Drivers!$B$49*(1+Drivers!$B$50)^0*(1-Drivers!$B$14)^11+Drivers!$B$49*(1+Drivers!$B$50)^1*(1-Drivers!$B$14)^10+Drivers!$B$49*(1+Drivers!$B$50)^2*(1-Drivers!$B$14)^9+Drivers!$B$49*(1+Drivers!$B$50)^3*(1-Drivers!$B$14)^8+Drivers!$B$49*(1+Drivers!$B$50)^4*(1-Drivers!$B$14)^7+Drivers!$B$49*(1+Drivers!$B$50)^5*(1-Drivers!$B$14)^6+Drivers!$B$49*(1+Drivers!$B$50)^6*(1-Drivers!$B$14)^5+Drivers!$B$49*(1+Drivers!$B$50)^7*(1-Drivers!$B$14)^4+Drivers!$B$49*(1+Drivers!$B$50)^8*(1-Drivers!$B$14)^3+Drivers!$B$49*(1+Drivers!$B$50)^9*(1-Drivers!$B$14)^2+Drivers!$B$49*(1+Drivers!$B$50)^10*(1-Drivers!$B$14)^1+Drivers!$B$49*(1+Drivers!$B$50)^11*(1-Drivers!$B$14)^0)*Drivers!$B$28) | C6: =12*((Drivers!$C$47*(1+Drivers!$C$48)^0*(1-Drivers!$B$15)^11+Drivers!$C$47*(1+Drivers!$C$48)^1*(1-Drivers!$B$15)^10+Drivers!$C$47*(1+Drivers!$C$48)^2*(1-Drivers!$B$15)^9+Drivers!$C$47*(1+Drivers!$C$48)^3*(1-Drivers!$B$15)^8+Drivers!$C$47*(1+Drivers!$C$48)^4*(1-Drivers!$B$15)^7+Drivers!$C$47*(1+Drivers!$C$48)^5*(1-Drivers!$B$15)^6+Drivers!$C$47*(1+Drivers!$C$48)^6*(1-Drivers!$B$15)^5+Drivers!$C$47*(1+Drivers!$C$48)^7*(1-Drivers!$B$15)^4+Drivers!$C$47*(1+Drivers!$C$48)^8*(1-Drivers!$B$15)^3+Drivers!$C$47*(1+Drivers!$C$48)^9*(1-Drivers!$B$15)^2+Drivers!$C$47*(1+Drivers!$C$48)^10*(1-Drivers!$B$15)^1+Drivers!$C$47*(1+Drivers!$C$48)^11*(1-Drivers!$B$15)^0)*Drivers!$B$29+(Drivers!$C$49*(1+Drivers!$C$50)^0*(1-Drivers!$B$14)^11+Drivers!$C$49*(1+Drivers!$C$50)^1*(1-Drivers!$B$14)^10+Drivers!$C$49*(1+Drivers!$C$50)^2*(1-Drivers!$B$14)^9+Drivers!$C$49*(1+Drivers!$C$50)^3*(1-Drivers!$B$14)^8+Drivers!$C$49*(1+Drivers!$C$50)^4*(1-Drivers!$B$14)^7+Drivers!$C$49*(1+Drivers!$C$50)^5*(1-Drivers!$B$14)^6+Drivers!$C$49*(1+Drivers!$C$50)^6*(1-Drivers!$B$14)^5+Drivers!$C$49*(1+Drivers!$C$50)^7*(1-Drivers!$B$14)^4+Drivers!$C$49*(1+Drivers!$C$50)^8*(1-Drivers!$B$14)^3+Drivers!$C$49*(1+Drivers!$C$50)^9*(1-Drivers!$B$14)^2+Drivers!$C$49*(1+Drivers!$C$50)^10*(1-Drivers!$B$14)^1+Drivers!$C$49*(1+Drivers!$C$50)^11*(1-Drivers!$B$14)^0)*Drivers!$B$28) | D6: =12*((Drivers!$D$47*(1+Drivers!$D$48)^0*(1-Drivers!$B$15)^11+Drivers!$D$47*(1+Drivers!$D$48)^1*(1-Drivers!$B$15)^10+Drivers!$D$47*(1+Drivers!$D$48)^2*(1-Drivers!$B$15)^9+Drivers!$D$47*(1+Drivers!$D$48)^3*(1-Drivers!$B$15)^8+Drivers!$D$47*(1+Drivers!$D$48)^4*(1-Drivers!$B$15)^7+Drivers!$D$47*(1+Drivers!$D$48)^5*(1-Drivers!$B$15)^6+Drivers!$D$47*(1+Drivers!$D$48)^6*(1-Drivers!$B$15)^5+Drivers!$D$47*(1+Drivers!$D$48)^7*(1-Drivers!$B$15)^4+Drivers!$D$47*(1+Drivers!$D$48)^8*(1-Drivers!$B$15)^3+Drivers!$D$47*(1+Drivers!$D$48)^9*(1-Drivers!$B$15)^2+Drivers!$D$47*(1+Drivers!$D$48)^10*(1-Drivers!$B$15)^1+Drivers!$D$47*(1+Drivers!$D$48)^11*(1-Drivers!$B$15)^0)*Drivers!$B$29+(Drivers!$D$49*(1+Drivers!$D$50)^0*(1-Drivers!$B$14)^11+Drivers!$D$49*(1+Drivers!$D$50)^1*(1-Drivers!$B$14)^10+Drivers!$D$49*(1+Drivers!$D$50)^2*(1-Drivers!$B$14)^9+Drivers!$D$49*(1+Drivers!$D$50)^3*(1-Drivers!$B$14)^8+Drivers!$D$49*(1+Drivers!$D$50)^4*(1-Drivers!$B$14)^7+Drivers!$D$49*(1+Drivers!$D$50)^5*(1-Drivers!$B$14)^6+Drivers!$D$49*(1+Drivers!$D$50)^6*(1-Drivers!$B$14)^5+Drivers!$D$49*(1+Drivers!$D$50)^7*(1-Drivers!$B$14)^4+Drivers!$D$49*(1+Drivers!$D$50)^8*(1-Drivers!$B$14)^3+Drivers!$D$49*(1+Drivers!$D$50)^9*(1-Drivers!$B$14)^2+Drivers!$D$49*(1+Drivers!$D$50)^10*(1-Drivers!$B$14)^1+Drivers!$D$49*(1+Drivers!$D$50)^11*(1-Drivers!$B$14)^0)*Drivers!$B$28) | E6: =Projection!$M$10*12
A8: Active scenario: | B8: =CHOOSE(Drivers!$B$43,"Conservative","Base","Aggressive")
A9: Note: ACTIVE column = live Projection tab; toggle Drivers!B43 (1/2/3).

Sheet Sensitivity
A1: KLARAVEX - Sensitivity: Breakeven Month & M12 ARR vs Deflection x Churn
A3: TABLE 1 - M12 ARR run-rate ($)
A4: Deflect \ Churn | B4: 0.03 | C4: 0.04 | D4: 0.05 | E4: 0.06 | F4: 0.07 | G4: 0.08 | H4: 0.09
A5: 0.55 | B5: =12*((Drivers!$E$47*(1+Drivers!$E$48)^0*(1-B$4)^11+Drivers!$E$47*(1+Drivers!$E$48)^1*(1-B$4)^10+Drivers!$E$47*(1+Drivers!$E$48)^2*(1-B$4)^9+Drivers!$E$47*(1+Drivers!$E$48)^3*(1-B$4)^8+Drivers!$E$47*(1+Drivers!$E$48)^4*(1-B$4)^7+Drivers!$E$47*(1+Drivers!$E$48)^5*(1-B$4)^6+Drivers!$E$47*(1+Drivers!$E$48)^6*(1-B$4)^5+Drivers!$E$47*(1+Drivers!$E$48)^7*(1-B$4)^4+Drivers!$E$47*(1+Drivers!$E$48)^8*(1-B$4)^3+Drivers!$E$47*(1+Drivers!$E$48)^9*(1-B$4)^2+Drivers!$E$47*(1+Drivers!$E$48)^10*(1-B$4)^1+Drivers!$E$47*(1+Drivers!$E$48)^11*(1-B$4)^0)*Drivers!$B$29+(Drivers!$E$49*(1+Drivers!$E$50)^0*(1-Drivers!$B$14)^11+Drivers!$E$49*(1+Drivers!$E$50)^1*(1-Drivers!$B$14)^10+Drivers!$E$49*(1+Drivers!$E$50)^2*(1-Drivers!$B$14)^9+Drivers!$E$49*(1+Drivers!$E$50)^3*(1-Drivers!$B$14)^8+Drivers!$E$49*(1+Drivers!$E$50)^4*(1-Drivers!$B$14)^7+Drivers!$E$49*(1+Drivers!$E$50)^5*(1-Drivers!$B$14)^6+Drivers!$E$49*(1+Drivers!$E$50)^6*(1-Drivers!$B$14)^5+Drivers!$E$49*(1+Drivers!$E$50)^7*(1-Drivers!$B$14)^4+Drivers!$E$49*(1+Drivers!$E$50)^8*(1-Drivers!$B$14)^3+Drivers!$E$49*(1+Drivers!$E$50)^9*(1-Drivers!$B$14)^2+Drivers!$E$49*(1+Drivers!$E$50)^10*(1-Drivers!$B$14)^1+Drivers!$E$49*(1+Drivers!$E$50)^11*(1-Drivers!$B$14)^0)*Drivers!$B$28) | C5: =12*((Drivers!$E$47*(1+Drivers!$E$48)^0*(1-C$4)^11+Drivers!$E$47*(1+Drivers!$E$48)^1*(1-C$4)^10+Drivers!$E$47*(1+Drivers!$E$48)^2*(1-C$4)^9+Drivers!$E$47*(1+Drivers!$E$48)^3*(1-C$4)^8+Drivers!$E$47*(1+Drivers!$E$48)^4*(1-C$4)^7+Drivers!$E$47*(1+Drivers!$E$48)^5*(1-C$4)^6+Drivers!$E$47*(1+Drivers!$E$48)^6*(1-C$4)^5+Drivers!$E$47*(1+Drivers!$E$48)^7*(1-C$4)^4+Drivers!$E$47*(1+Drivers!$E$48)^8*(1-C$4)^3+Drivers!$E$47*(1+Drivers!$E$48)^9*(1-C$4)^2+Drivers!$E$47*(1+Drivers!$E$48)^10*(1-C$4)^1+Drivers!$E$47*(1+Drivers!$E$48)^11*(1-C$4)^0)*Drivers!$B$29+(Drivers!$E$49*(1+Drivers!$E$50)^0*(1-Drivers!$B$14)^11+Drivers!$E$49*(1+Drivers!$E$50)^1*(1-Drivers!$B$14)^10+Drivers!$E$49*(1+Drivers!$E$50)^2*(1-Drivers!$B$14)^9+Drivers!$E$49*(1+Drivers!$E$50)^3*(1-Drivers!$B$14)^8+Drivers!$E$49*(1+Drivers!$E$50)^4*(1-Drivers!$B$14)^7+Drivers!$E$49*(1+Drivers!$E$50)^5*(1-Drivers!$B$14)^6+Drivers!$E$49*(1+Drivers!$E$50)^6*(1-Drivers!$B$14)^5+Drivers!$E$49*(1+Drivers!$E$50)^7*(1-Drivers!$B$14)^4+Drivers!$E$49*(1+Drivers!$E$50)^8*(1-Drivers!$B$14)^3+Drivers!$E$49*(1+Drivers!$E$50)^9*(1-Drivers!$B$14)^2+Drivers!$E$49*(1+Drivers!$E$50)^10*(1-Drivers!$B$14)^1+Drivers!$E$49*(1+Drivers!$E$50)^11*(1-Drivers!$B$14)^0)*Drivers!$B$28) | D5: =12*((Drivers!$E$47*(1+Drivers!$E$48)^0*(1-D$4)^11+Drivers!$E$47*(1+Drivers!$E$48)^1*(1-D$4)^10+Drivers!$E$47*(1+Drivers!$E$48)^2*(1-D$4)^9+Drivers!$E$47*(1+Drivers!$E$48)^3*(1-D$4)^8+Drivers!$E$47*(1+Drivers!$E$48)^4*(1-D$4)^7+Drivers!$E$47*(1+Drivers!$E$48)^5*(1-D$4)^6+Drivers!$E$47*(1+Drivers!$E$48)^6*(1-D$4)^5+Drivers!$E$47*(1+Drivers!$E$48)^7*(1-D$4)^4+Drivers!$E$47*(1+Drivers!$E$48)^8*(1-D$4)^3+Drivers!$E$47*(1+Drivers!$E$48)^9*(1-D$4)^2+Drivers!$E$47*(1+Drivers!$E$48)^10*(1-D$4)^1+Drivers!$E$47*(1+Drivers!$E$48)^11*(1-D$4)^0)*Drivers!$B$29+(Drivers!$E$49*(1+Drivers!$E$50)^0*(1-Drivers!$B$14)^11+Drivers!$E$49*(1+Drivers!$E$50)^1*(1-Drivers!$B$14)^10+Drivers!$E$49*(1+Drivers!$E$50)^2*(1-Drivers!$B$14)^9+Drivers!$E$49*(1+Drivers!$E$50)^3*(1-Drivers!$B$14)^8+Drivers!$E$49*(1+Drivers!$E$50)^4*(1-Drivers!$B$14)^7+Drivers!$E$49*(1+Drivers!$E$50)^5*(1-Drivers!$B$14)^6+Drivers!$E$49*(1+Drivers!$E$50)^6*(1-Drivers!$B$14)^5+Drivers!$E$49*(1+Drivers!$E$50)^7*(1-Drivers!$B$14)^4+Drivers!$E$49*(1+Drivers!$E$50)^8*(1-Drivers!$B$14)^3+Drivers!$E$49*(1+Drivers!$E$50)^9*(1-Drivers!$B$14)^2+Drivers!$E$49*(1+Drivers!$E$50)^10*(1-Drivers!$B$14)^1+Drivers!$E$49*(1+Drivers!$E$50)^11*(1-Drivers!$B$14)^0)*Drivers!$B$28) | E5: =12*((Drivers!$E$47*(1+Drivers!$E$48)^0*(1-E$4)^11+Drivers!$E$47*(1+Drivers!$E$48)^1*(1-E$4)^10+Drivers!$E$47*(1+Drivers!$E$48)^2*(1-E$4)^9+Drivers!$E$47*(1+Drivers!$E$48)^3*(1-E$4)^8+Drivers!$E$47*(1+Drivers!$E$48)^4*(1-E$4)^7+Drivers!$E$47*(1+Drivers!$E$48)^5*(1-E$4)^6+Drivers!$E$47*(1+Drivers!$E$48)^6*(1-E$4)^5+Drivers!$E$47*(1+Drivers!$E$48)^7*(1-E$4)^4+Drivers!$E$47*(1+Drivers!$E$48)^8*(1-E$4)^3+Drivers!$E$47*(1+Drivers!$E$48)^9*(1-E$4)^2+Drivers!$E$47*(1+Drivers!$E$48)^10*(1-E$4)^1+Drivers!$E$47*(1+Drivers!$E$48)^11*(1-E$4)^0)*Drivers!$B$29+(Drivers!$E$49*(1+Drivers!$E$50)^0*(1-Drivers!$B$14)^11+Drivers!$E$49*(1+Drivers!$E$50)^1*(1-Drivers!$B$14)^10+Drivers!$E$49*(1+Drivers!$E$50)^2*(1-Drivers!$B$14)^9+Drivers!$E$49*(1+Drivers!$E$50)^3*(1-Drivers!$B$14)^8+Drivers!$E$49*(1+Drivers!$E$50)^4*(1-Drivers!$B$14)^7+Drivers!$E$49*(1+Drivers!$E$50)^5*(1-Drivers!$B$14)^6+Drivers!$E$49*(1+Drivers!$E$50)^6*(1-Drivers!$B$14)^5+Drivers!$E$49*(1+Drivers!$E$50)^7*(1-Drivers!$B$14)^4+Drivers!$E$49*(1+Drivers!$E$50)^8*(1-Drivers!$B$14)^3+Drivers!$E$49*(1+Drivers!$E$50)^9*(1-Drivers!$B$14)^2+Drivers!$E$49*(1+Drivers!$E$50)^10*(1-Drivers!$B$14)^1+Drivers!$E$49*(1+Drivers!$E$50)^11*(1-Drivers!$B$14)^0)*Drivers!$B$28) | F5: =12*((Drivers!$E$47*(1+Drivers!$E$48)^0*(1-F$4)^11+Drivers!$E$47*(1+Drivers!$E$48)^1*(1-F$4)^10+Drivers!$E$47*(1+Drivers!$E$48)^2*(1-F$4)^9+Drivers!$E$47*(1+Drivers!$E$48)^3*(1-F$4)^8+Drivers!$E$47*(1+Drivers!$E$48)^4*(1-F$4)^7+Drivers!$E$47*(1+Drivers!$E$48)^5*(1-F$4)^6+Drivers!$E$47*(1+Drivers!$E$48)^6*(1-F$4)^5+Drivers!$E$47*(1+Drivers!$E$48)^7*(1-F$4)^4+Drivers!$E$47*(1+Drivers!$E$48)^8*(1-F$4)^3+Drivers!$E$47*(1+Drivers!$E$48)^9*(1-F$4)^2+Drivers!$E$47*(1+Drivers!$E$48)^10*(1-F$4)^1+Drivers!$E$47*(1+Drivers!$E$48)^11*(1-F$4)^0)*Drivers!$B$29+(Drivers!$E$49*(1+Drivers!$E$50)^0*(1-Drivers!$B$14)^11+Drivers!$E$49*(1+Drivers!$E$50)^1*(1-Drivers!$B$14)^10+Drivers!$E$49*(1+Drivers!$E$50)^2*(1-Drivers!$B$14)^9+Drivers!$E$49*(1+Drivers!$E$50)^3*(1-Drivers!$B$14)^8+Drivers!$E$49*(1+Drivers!$E$50)^4*(1-Drivers!$B$14)^7+Drivers!$E$49*(1+Drivers!$E$50)^5*(1-Drivers!$B$14)^6+Drivers!$E$49*(1+Drivers!$E$50)^6*(1-Drivers!$B$14)^5+Drivers!$E$49*(1+Drivers!$E$50)^7*(1-Drivers!$B$14)^4+Drivers!$E$49*(1+Drivers!$E$50)^8*(1-Drivers!$B$14)^3+Drivers!$E$49*(1+Drivers!$E$50)^9*(1-Drivers!$B$14)^2+Drivers!$E$49*(1+Drivers!$E$50)^10*(1-Drivers!$B$14)^1+Drivers!$E$49*(1+Drivers!$E$50)^11*(1-Drivers!$B$14)^0)*Drivers!$B$28) | G5: =12*((Drivers!$E$47*(1+Drivers!$E$48)^0*(1-G$4)^11+Drivers!$E$47*(1+Drivers!$E$48)^1*(1-G$4)^10+Drivers!$E$47*(1+Drivers!$E$48)^2*(1-G$4)^9+Drivers!$E$47*(1+Drivers!$E$48)^3*(1-G$4)^8+Drivers!$E$47*(1+Drivers!$E$48)^4*(1-G$4)^7+Drivers!$E$47*(1+Drivers!$E$48)^5*(1-G$4)^6+Drivers!$E$47*(1+Drivers!$E$48)^6*(1-G$4)^5+Drivers!$E$47*(1+Drivers!$E$48)^7*(1-G$4)^4+Drivers!$E$47*(1+Drivers!$E$48)^8*(1-G$4)^3+Drivers!$E$47*(1+Drivers!$E$48)^9*(1-G$4)^2+Drivers!$E$47*(1+Drivers!$E$48)^10*(1-G$4)^1+Drivers!$E$47*(1+Drivers!$E$48)^11*(1-G$4)^0)*Drivers!$B$29+(Drivers!$E$49*(1+Drivers!$E$50)^0*(1-Drivers!$B$14)^11+Drivers!$E$49*(1+Drivers!$E$50)^1*(1-Drivers!$B$14)^10+Drivers!$E$49*(1+Drivers!$E$50)^2*(1-Drivers!$B$14)^9+Drivers!$E$49*(1+Drivers!$E$50)^3*(1-Drivers!$B$14)^8+Drivers!$E$49*(1+Drivers!$E$50)^4*(1-Drivers!$B$14)^7+Drivers!$E$49*(1+Drivers!$E$50)^5*(1-Drivers!$B$14)^6+Drivers!$E$49*(1+Drivers!$E$50)^6*(1-Drivers!$B$14)^5+Drivers!$E$49*(1+Drivers!$E$50)^7*(1-Drivers!$B$14)^4+Drivers!$E$49*(1+Drivers!$E$50)^8*(1-Drivers!$B$14)^3+Drivers!$E$49*(1+Drivers!$E$50)^9*(1-Drivers!$B$14)^2+Drivers!$E$49*(1+Drivers!$E$50)^10*(1-Drivers!$B$14)^1+Drivers!$E$49*(1+Drivers!$E$50)^11*(1-Drivers!$B$14)^0)*Drivers!$B$28) | H5: =12*((Drivers!$E$47*(1+Drivers!$E$48)^0*(1-H$4)^11+Drivers!$E$47*(1+Drivers!$E$48)^1*(1-H$4)^10+Drivers!$E$47*(1+Drivers!$E$48)^2*(1-H$4)^9+Drivers!$E$47*(1+Drivers!$E$48)^3*(1-H$4)^8+Drivers!$E$47*(1+Drivers!$E$48)^4*(1-H$4)^7+Drivers!$E$47*(1+Drivers!$E$48)^5*(1-H$4)^6+Drivers!$E$47*(1+Drivers!$E$48)^6*(1-H$4)^5+Drivers!$E$47*(1+Drivers!$E$48)^7*(1-H$4)^4+Drivers!$E$47*(1+Drivers!$E$48)^8*(1-H$4)^3+Drivers!$E$47*(1+Drivers!$E$48)^9*(1-H$4)^2+Drivers!$E$47*(1+Drivers!$E$48)^10*(1-H$4)^1+Drivers!$E$47*(1+Drivers!$E$48)^11*(1-H$4)^0)*Drivers!$B$29+(Drivers!$E$49*(1+Drivers!$E$50)^0*(1-Drivers!$B$14)^11+Drivers!$E$49*(1+Drivers!$E$50)^1*(1-Drivers!$B$14)^10+Drivers!$E$49*(1+Drivers!$E$50)^2*(1-Drivers!$B$14)^9+Drivers!$E$49*(1+Drivers!$E$50)^3*(1-Drivers!$B$14)^8+Drivers!$E$49*(1+Drivers!$E$50)^4*(1-Drivers!$B$14)^7+Drivers!$E$49*(1+Drivers!$E$50)^5*(1-Drivers!$B$14)^6+Drivers!$E$49*(1+Drivers!$E$50)^6*(1-Drivers!$B$14)^5+Drivers!$E$49*(1+Drivers!$E$50)^7*(1-Drivers!$B$14)^4+Drivers!$E$49*(1+Drivers!$E$50)^8*(1-Drivers!$B$14)^3+Drivers!$E$49*(1+Drivers!$E$50)^9*(1-Drivers!$B$14)^2+Drivers!$E$49*(1+Drivers!$E$50)^10*(1-Drivers!$B$14)^1+Drivers!$E$49*(1+Drivers!$E$50)^11*(1-Drivers!$B$14)^0)*Drivers!$B$28)
A6: 0.6 | B6: =12*((Drivers!$E$47*(1+Drivers!$E$48)^0*(1-B$4)^11+Drivers!$E$47*(1+Drivers!$E$48)^1*(1-B$4)^10+Drivers!$E$47*(1+Drivers!$E$48)^2*(1-B$4)^9+Drivers!$E$47*(1+Drivers!$E$48)^3*(1-B$4)^8+Drivers!$E$47*(1+Drivers!$E$48)^4*(1-B$4)^7+Drivers!$E$47*(1+Drivers!$E$48)^5*(1-B$4)^6+Drivers!$E$47*(1+Drivers!$E$48)^6*(1-B$4)^5+Drivers!$E$47*(1+Drivers!$E$48)^7*(1-B$4)^4+Drivers!$E$47*(1+Drivers!$E$48)^8*(1-B$4)^3+Drivers!$E$47*(1+Drivers!$E$48)^9*(1-B$4)^2+Drivers!$E$47*(1+Drivers!$E$48)^10*(1-B$4)^1+Drivers!$E$47*(1+Drivers!$E$48)^11*(1-B$4)^0)*Drivers!$B$29+(Drivers!$E$49*(1+Drivers!$E$50)^0*(1-Drivers!$B$14)^11+Drivers!$E$49*(1+Drivers!$E$50)^1*(1-Drivers!$B$14)^10+Drivers!$E$49*(1+Drivers!$E$50)^2*(1-Drivers!$B$14)^9+Drivers!$E$49*(1+Drivers!$E$50)^3*(1-Drivers!$B$14)^8+Drivers!$E$49*(1+Drivers!$E$50)^4*(1-Drivers!$B$14)^7+Drivers!$E$49*(1+Drivers!$E$50)^5*(1-Drivers!$B$14)^6+Drivers!$E$49*(1+Drivers!$E$50)^6*(1-Drivers!$B$14)^5+Drivers!$E$49*(1+Drivers!$E$50)^7*(1-Drivers!$B$14)^4+Drivers!$E$49*(1+Drivers!$E$50)^8*(1-Drivers!$B$14)^3+Drivers!$E$49*(1+Drivers!$E$50)^9*(1-Drivers!$B$14)^2+Drivers!$E$49*(1+Drivers!$E$50)^10*(1-Drivers!$B$14)^1+Drivers!$E$49*(1+Drivers!$E$50)^11*(1-Drivers!$B$14)^0)*Drivers!$B$28) | C6: =12*((Drivers!$E$47*(1+Drivers!$E$48)^0*(1-C$4)^11+Drivers!$E$47*(1+Drivers!$E$48)^1*(1-C$4)^10+Drivers!$E$47*(1+Drivers!$E$48)^2*(1-C$4)^9+Drivers!$E$47*(1+Drivers!$E$48)^3*(1-C$4)^8+Drivers!$E$47*(1+Drivers!$E$48)^4*(1-C$4)^7+Drivers!$E$47*(1+Drivers!$E$48)^5*(1-C$4)^6+Drivers!$E$47*(1+Drivers!$E$48)^6*(1-C$4)^5+Drivers!$E$47*(1+Drivers!$E$48)^7*(1-C$4)^4+Drivers!$E$47*(1+Drivers!$E$48)^8*(1-C$4)^3+Drivers!$E$47*(1+Drivers!$E$48)^9*(1-C$4)^2+Drivers!$E$47*(1+Drivers!$E$48)^10*(1-C$4)^1+Drivers!$E$47*(1+Drivers!$E$48)^11*(1-C$4)^0)*Drivers!$B$29+(Drivers!$E$49*(1+Drivers!$E$50)^0*(1-Drivers!$B$14)^11+Drivers!$E$49*(1+Drivers!$E$50)^1*(1-Drivers!$B$14)^10+Drivers!$E$49*(1+Drivers!$E$50)^2*(1-Drivers!$B$14)^9+Drivers!$E$49*(1+Drivers!$E$50)^3*(1-Drivers!$B$14)^8+Drivers!$E$49*(1+Drivers!$E$50)^4*(1-Drivers!$B$14)^7+Drivers!$E$49*(1+Drivers!$E$50)^5*(1-Drivers!$B$14)^6+Drivers!$E$49*(1+Drivers!$E$50)^6*(1-Drivers!$B$14)^5+Drivers!$E$49*(1+Drivers!$E$50)^7*(1-Drivers!$B$14)^4+Drivers!$E$49*(1+Drivers!$E$50)^8*(1-Drivers!$B$14)^3+Drivers!$E$49*(1+Drivers!$E$50)^9*(1-Drivers!$B$14)^2+Drivers!$E$49*(1+Drivers!$E$50)^10*(1-Drivers!$B$14)^1+Drivers!$E$49*(1+Drivers!$E$50)^11*(1-Drivers!$B$14)^0)*Drivers!$B$28) | D6: =12*((Drivers!$E$47*(1+Drivers!$E$48)^0*(1-D$4)^11+Drivers!$E$47*(1+Drivers!$E$48)^1*(1-D$4)^10+Drivers!$E$47*(1+Drivers!$E$48)^2*(1-D$4)^9+Drivers!$E$47*(1+Drivers!$E$48)^3*(1-D$4)^8+Drivers!$E$47*(1+Drivers!$E$48)^4*(1-D$4)^7+Drivers!$E$47*(1+Drivers!$E$48)^5*(1-D$4)^6+Drivers!$E$47*(1+Drivers!$E$48)^6*(1-D$4)^5+Drivers!$E$47*(1+Drivers!$E$48)^7*(1-D$4)^4+Drivers!$E$47*(1+Drivers!$E$48)^8*(1-D$4)^3+Drivers!$E$47*(1+Drivers!$E$48)^9*(1-D$4)^2+Drivers!$E$47*(1+Drivers!$E$48)^10*(1-D$4)^1+Drivers!$E$47*(1+Drivers!$E$48)^11*(1-D$4)^0)*Drivers!$B$29+(Drivers!$E$49*(1+Drivers!$E$50)^0*(1-Drivers!$B$14)^11+Drivers!$E$49*(1+Drivers!$E$50)^1*(1-Drivers!$B$14)^10+Drivers!$E$49*(1+Drivers!$E$50)^2*(1-Drivers!$B$14)^9+Drivers!$E$49*(1+Drivers!$E$50)^3*(1-Drivers!$B$14)^8+Drivers!$E$49*(1+Drivers!$E$50)^4*(1-Drivers!$B$14)^7+Drivers!$E$49*(1+Drivers!$E$50)^5*(1-Drivers!$B$14)^6+Drivers!$E$49*(1+Drivers!$E$50)^6*(1-Drivers!$B$14)^5+Drivers!$E$49*(1+Drivers!$E$50)^7*(1-Drivers!$B$14)^4+Drivers!$E$49*(1+Drivers!$E$50)^8*(1-Drivers!$B$14)^3+Drivers!$E$49*(1+Drivers!$E$50)^9*(1-Drivers!$B$14)^2+Drivers!$E$49*(1+Drivers!$E$50)^10*(1-Drivers!$B$14)^1+Drivers!$E$49*(1+Drivers!$E$50)^11*(1-Drivers!$B$14)^0)*Drivers!$B$28) | E6: =12*((Drivers!$E$47*(1+Drivers!$E$48)^0*(1-E$4)^11+Drivers!$E$47*(1+Drivers!$E$48)^1*(1-E$4)^10+Drivers!$E$47*(1+Drivers!$E$48)^2*(1-E$4)^9+Drivers!$E$47*(1+Drivers!$E$48)^3*(1-E$4)^8+Drivers!$E$47*(1+Drivers!$E$48)^4*(1-E$4)^7+Drivers!$E$47*(1+Drivers!$E$48)^5*(1-E$4)^6+Drivers!$E$47*(1+Drivers!$E$48)^6*(1-E$4)^5+Drivers!$E$47*(1+Drivers!$E$48)^7*(1-E$4)^4+Drivers!$E$47*(1+Drivers!$E$48)^8*(1-E$4)^3+Drivers!$E$47*(1+Drivers!$E$48)^9*(1-E$4)^2+Drivers!$E$47*(1+Drivers!$E$48)^10*(1-E$4)^1+Drivers!$E$47*(1+Drivers!$E$48)^11*(1-E$4)^0)*Drivers!$B$29+(Drivers!$E$49*(1+Drivers!$E$50)^0*(1-Drivers!$B$14)^11+Drivers!$E$49*(1+Drivers!$E$50)^1*(1-Drivers!$B$14)^10+Drivers!$E$49*(1+Drivers!$E$50)^2*(1-Drivers!$B$14)^9+Drivers!$E$49*(1+Drivers!$E$50)^3*(1-Drivers!$B$14)^8+Drivers!$E$49*(1+Drivers!$E$50)^4*(1-Drivers!$B$14)^7+Drivers!$E$49*(1+Drivers!$E$50)^5*(1-Drivers!$B$14)^6+Drivers!$E$49*(1+Drivers!$E$50)^6*(1-Drivers!$B$14)^5+Drivers!$E$49*(1+Drivers!$E$50)^7*(1-Drivers!$B$14)^4+Drivers!$E$49*(1+Drivers!$E$50)^8*(1-Drivers!$B$14)^3+Drivers!$E$49*(1+Drivers!$E$50)^9*(1-Drivers!$B$14)^2+Drivers!$E$49*(1+Drivers!$E$50)^10*(1-Drivers!$B$14)^1+Drivers!$E$49*(1+Drivers!$E$50)^11*(1-Drivers!$B$14)^0)*Drivers!$B$28) | F6: =12*((Drivers!$E$47*(1+Drivers!$E$48)^0*(1-F$4)^11+Drivers!$E$47*(1+Drivers!$E$48)^1*(1-F$4)^10+Drivers!$E$47*(1+Drivers!$E$48)^2*(1-F$4)^9+Drivers!$E$47*(1+Drivers!$E$48)^3*(1-F$4)^8+Drivers!$E$47*(1+Drivers!$E$48)^4*(1-F$4)^7+Drivers!$E$47*(1+Drivers!$E$48)^5*(1-F$4)^6+Drivers!$E$47*(1+Drivers!$E$48)^6*(1-F$4)^5+Drivers!$E$47*(1+Drivers!$E$48)^7*(1-F$4)^4+Drivers!$E$47*(1+Drivers!$E$48)^8*(1-F$4)^3+Drivers!$E$47*(1+Drivers!$E$48)^9*(1-F$4)^2+Drivers!$E$47*(1+Drivers!$E$48)^10*(1-F$4)^1+Drivers!$E$47*(1+Drivers!$E$48)^11*(1-F$4)^0)*Drivers!$B$29+(Drivers!$E$49*(1+Drivers!$E$50)^0*(1-Drivers!$B$14)^11+Drivers!$E$49*(1+Drivers!$E$50)^1*(1-Drivers!$B$14)^10+Drivers!$E$49*(1+Drivers!$E$50)^2*(1-Drivers!$B$14)^9+Drivers!$E$49*(1+Drivers!$E$50)^3*(1-Drivers!$B$14)^8+Drivers!$E$49*(1+Drivers!$E$50)^4*(1-Drivers!$B$14)^7+Drivers!$E$49*(1+Drivers!$E$50)^5*(1-Drivers!$B$14)^6+Drivers!$E$49*(1+Drivers!$E$50)^6*(1-Drivers!$B$14)^5+Drivers!$E$49*(1+Drivers!$E$50)^7*(1-Drivers!$B$14)^4+Drivers!$E$49*(1+Drivers!$E$50)^8*(1-Drivers!$B$14)^3+Drivers!$E$49*(1+Drivers!$E$50)^9*(1-Drivers!$B$14)^2+Drivers!$E$49*(1+Drivers!$E$50)^10*(1-Drivers!$B$14)^1+Drivers!$E$49*(1+Drivers!$E$50)^11*(1-Drivers!$B$14)^0)*Drivers!$B$28) | G6: =12*((Drivers!$E$47*(1+Drivers!$E$48)^0*(1-G$4)^11+Drivers!$E$47*(1+Drivers!$E$48)^1*(1-G$4)^10+Drivers!$E$47*(1+Drivers!$E$48)^2*(1-G$4)^9+Drivers!$E$47*(1+Drivers!$E$48)^3*(1-G$4)^8+Drivers!$E$47*(1+Drivers!$E$48)^4*(1-G$4)^7+Drivers!$E$47*(1+Drivers!$E$48)^5*(1-G$4)^6+Drivers!$E$47*(1+Drivers!$E$48)^6*(1-G$4)^5+Drivers!$E$47*(1+Drivers!$E$48)^7*(1-G$4)^4+Drivers!$E$47*(1+Drivers!$E$48)^8*(1-G$4)^3+Drivers!$E$47*(1+Drivers!$E$48)^9*(1-G$4)^2+Drivers!$E$47*(1+Drivers!$E$48)^10*(1-G$4)^1+Drivers!$E$47*(1+Drivers!$E$48)^11*(1-G$4)^0)*Drivers!$B$29+(Drivers!$E$49*(1+Drivers!$E$50)^0*(1-Drivers!$B$14)^11+Drivers!$E$49*(1+Drivers!$E$50)^1*(1-Drivers!$B$14)^10+Drivers!$E$49*(1+Drivers!$E$50)^2*(1-Drivers!$B$14)^9+Drivers!$E$49*(1+Drivers!$E$50)^3*(1-Drivers!$B$14)^8+Drivers!$E$49*(1+Drivers!$E$50)^4*(1-Drivers!$B$14)^7+Drivers!$E$49*(1+Drivers!$E$50)^5*(1-Drivers!$B$14)^6+Drivers!$E$49*(1+Drivers!$E$50)^6*(1-Drivers!$B$14)^5+Drivers!$E$49*(1+Drivers!$E$50)^7*(1-Drivers!$B$14)^4+Drivers!$E$49*(1+Drivers!$E$50)^8*(1-Drivers!$B$14)^3+Drivers!$E$49*(1+Drivers!$E$50)^9*(1-Drivers!$B$14)^2+Drivers!$E$49*(1+Drivers!$E$50)^10*(1-Drivers!$B$14)^1+Drivers!$E$49*(1+Drivers!$E$50)^11*(1-Drivers!$B$14)^0)*Drivers!$B$28) | H6: =12*((Drivers!$E$47*(1+Drivers!$E$48)^0*(1-H$4)^11+Drivers!$E$47*(1+Drivers!$E$48)^1*(1-H$4)^10+Drivers!$E$47*(1+Drivers!$E$48)^2*(1-H$4)^9+Drivers!$E$47*(1+Drivers!$E$48)^3*(1-H$4)^8+Drivers!$E$47*(1+Drivers!$E$48)^4*(1-H$4)^7+Drivers!$E$47*(1+Drivers!$E$48)^5*(1-H$4)^6+Drivers!$E$47*(1+Drivers!$E$48)^6*(1-H$4)^5+Drivers!$E$47*(1+Drivers!$E$48)^7*(1-H$4)^4+Drivers!$E$47*(1+Drivers!$E$48)^8*(1-H$4)^3+Drivers!$E$47*(1+Drivers!$E$48)^9*(1-H$4)^2+Drivers!$E$47*(1+Drivers!$E$48)^10*(1-H$4)^1+Drivers!$E$47*(1+Drivers!$E$48)^11*(1-H$4)^0)*Drivers!$B$29+(Drivers!$E$49*(1+Drivers!$E$50)^0*(1-Drivers!$B$14)^11+Drivers!$E$49*(1+Drivers!$E$50)^1*(1-Drivers!$B$14)^10+Drivers!$E$49*(1+Drivers!$E$50)^2*(1-Drivers!$B$14)^9+Drivers!$E$49*(1+Drivers!$E$50)^3*(1-Drivers!$B$14)^8+Drivers!$E$49*(1+Drivers!$E$50)^4*(1-Drivers!$B$14)^7+Drivers!$E$49*(1+Drivers!$E$50)^5*(1-Drivers!$B$14)^6+Drivers!$E$49*(1+Drivers!$E$50)^6*(1-Drivers!$B$14)^5+Drivers!$E$49*(1+Drivers!$E$50)^7*(1-Drivers!$B$14)^4+Drivers!$E$49*(1+Drivers!$E$50)^8*(1-Drivers!$B$14)^3+Drivers!$E$49*(1+Drivers!$E$50)^9*(1-Drivers!$B$14)^2+Drivers!$E$49*(1+Drivers!$E$50)^10*(1-Drivers!$B$14)^1+Drivers!$E$49*(1+Drivers!$E$50)^11*(1-Drivers!$B$14)^0)*Drivers!$B$28)
A7: 0.65 | B7: =12*((Drivers!$E$47*(1+Drivers!$E$48)^0*(1-B$4)^11+Drivers!$E$47*(1+Drivers!$E$48)^1*(1-B$4)^10+Drivers!$E$47*(1+Drivers!$E$48)^2*(1-B$4)^9+Drivers!$E$47*(1+Drivers!$E$48)^3*(1-B$4)^8+Drivers!$E$47*(1+Drivers!$E$48)^4*(1-B$4)^7+Drivers!$E$47*(1+Drivers!$E$48)^5*(1-B$4)^6+Drivers!$E$47*(1+Drivers!$E$48)^6*(1-B$4)^5+Drivers!$E$47*(1+Drivers!$E$48)^7*(1-B$4)^4+Drivers!$E$47*(1+Drivers!$E$48)^8*(1-B$4)^3+Drivers!$E$47*(1+Drivers!$E$48)^9*(1-B$4)^2+Drivers!$E$47*(1+Drivers!$E$48)^10*(1-B$4)^1+Drivers!$E$47*(1+Drivers!$E$48)^11*(1-B$4)^0)*Drivers!$B$29+(Drivers!$E$49*(1+Drivers!$E$50)^0*(1-Drivers!$B$14)^11+Drivers!$E$49*(1+Drivers!$E$50)^1*(1-Drivers!$B$14)^10+Drivers!$E$49*(1+Drivers!$E$50)^2*(1-Drivers!$B$14)^9+Drivers!$E$49*(1+Drivers!$E$50)^3*(1-Drivers!$B$14)^8+Drivers!$E$49*(1+Drivers!$E$50)^4*(1-Drivers!$B$14)^7+Drivers!$E$49*(1+Drivers!$E$50)^5*(1-Drivers!$B$14)^6+Drivers!$E$49*(1+Drivers!$E$50)^6*(1-Drivers!$B$14)^5+Drivers!$E$49*(1+Drivers!$E$50)^7*(1-Drivers!$B$14)^4+Drivers!$E$49*(1+Drivers!$E$50)^8*(1-Drivers!$B$14)^3+Drivers!$E$49*(1+Drivers!$E$50)^9*(1-Drivers!$B$14)^2+Drivers!$E$49*(1+Drivers!$E$50)^10*(1-Drivers!$B$14)^1+Drivers!$E$49*(1+Drivers!$E$50)^11*(1-Drivers!$B$14)^0)*Drivers!$B$28) | C7: =12*((Drivers!$E$47*(1+Drivers!$E$48)^0*(1-C$4)^11+Drivers!$E$47*(1+Drivers!$E$48)^1*(1-C$4)^10+Drivers!$E$47*(1+Drivers!$E$48)^2*(1-C$4)^9+Drivers!$E$47*(1+Drivers!$E$48)^3*(1-C$4)^8+Drivers!$E$47*(1+Drivers!$E$48)^4*(1-C$4)^7+Drivers!$E$47*(1+Drivers!$E$48)^5*(1-C$4)^6+Drivers!$E$47*(1+Drivers!$E$48)^6*(1-C$4)^5+Drivers!$E$47*(1+Drivers!$E$48)^7*(1-C$4)^4+Drivers!$E$47*(1+Drivers!$E$48)^8*(1-C$4)^3+Drivers!$E$47*(1+Drivers!$E$48)^9*(1-C$4)^2+Drivers!$E$47*(1+Drivers!$E$48)^10*(1-C$4)^1+Drivers!$E$47*(1+Drivers!$E$48)^11*(1-C$4)^0)*Drivers!$B$29+(Drivers!$E$49*(1+Drivers!$E$50)^0*(1-Drivers!$B$14)^11+Drivers!$E$49*(1+Drivers!$E$50)^1*(1-Drivers!$B$14)^10+Drivers!$E$49*(1+Drivers!$E$50)^2*(1-Drivers!$B$14)^9+Drivers!$E$49*(1+Drivers!$E$50)^3*(1-Drivers!$B$14)^8+Drivers!$E$49*(1+Drivers!$E$50)^4*(1-Drivers!$B$14)^7+Drivers!$E$49*(1+Drivers!$E$50)^5*(1-Drivers!$B$14)^6+Drivers!$E$49*(1+Drivers!$E$50)^6*(1-Drivers!$B$14)^5+Drivers!$E$49*(1+Drivers!$E$50)^7*(1-Drivers!$B$14)^4+Drivers!$E$49*(1+Drivers!$E$50)^8*(1-Drivers!$B$14)^3+Drivers!$E$49*(1+Drivers!$E$50)^9*(1-Drivers!$B$14)^2+Drivers!$E$49*(1+Drivers!$E$50)^10*(1-Drivers!$B$14)^1+Drivers!$E$49*(1+Drivers!$E$50)^11*(1-Drivers!$B$14)^0)*Drivers!$B$28) | D7: =12*((Drivers!$E$47*(1+Drivers!$E$48)^0*(1-D$4)^11+Drivers!$E$47*(1+Drivers!$E$48)^1*(1-D$4)^10+Drivers!$E$47*(1+Drivers!$E$48)^2*(1-D$4)^9+Drivers!$E$47*(1+Drivers!$E$48)^3*(1-D$4)^8+Drivers!$E$47*(1+Drivers!$E$48)^4*(1-D$4)^7+Drivers!$E$47*(1+Drivers!$E$48)^5*(1-D$4)^6+Drivers!$E$47*(1+Drivers!$E$48)^6*(1-D$4)^5+Drivers!$E$47*(1+Drivers!$E$48)^7*(1-D$4)^4+Drivers!$E$47*(1+Drivers!$E$48)^8*(1-D$4)^3+Drivers!$E$47*(1+Drivers!$E$48)^9*(1-D$4)^2+Drivers!$E$47*(1+Drivers!$E$48)^10*(1-D$4)^1+Drivers!$E$47*(1+Drivers!$E$48)^11*(1-D$4)^0)*Drivers!$B$29+(Drivers!$E$49*(1+Drivers!$E$50)^0*(1-Drivers!$B$14)^11+Drivers!$E$49*(1+Drivers!$E$50)^1*(1-Drivers!$B$14)^10+Drivers!$E$49*(1+Drivers!$E$50)^2*(1-Drivers!$B$14)^9+Drivers!$E$49*(1+Drivers!$E$50)^3*(1-Drivers!$B$14)^8+Drivers!$E$49*(1+Drivers!$E$50)^4*(1-Drivers!$B$14)^7+Drivers!$E$49*(1+Drivers!$E$50)^5*(1-Drivers!$B$14)^6+Drivers!$E$49*(1+Drivers!$E$50)^6*(1-Drivers!$B$14)^5+Drivers!$E$49*(1+Drivers!$E$50)^7*(1-Drivers!$B$14)^4+Drivers!$E$49*(1+Drivers!$E$50)^8*(1-Drivers!$B$14)^3+Drivers!$E$49*(1+Drivers!$E$50)^9*(1-Drivers!$B$14)^2+Drivers!$E$49*(1+Drivers!$E$50)^10*(1-Drivers!$B$14)^1+Drivers!$E$49*(1+Drivers!$E$50)^11*(1-Drivers!$B$14)^0)*Drivers!$B$28) | E7: =12*((Drivers!$E$47*(1+Drivers!$E$48)^0*(1-E$4)^11+Drivers!$E$47*(1+Drivers!$E$48)^1*(1-E$4)^10+Drivers!$E$47*(1+Drivers!$E$48)^2*(1-E$4)^9+Drivers!$E$47*(1+Drivers!$E$48)^3*(1-E$4)^8+Drivers!$E$47*(1+Drivers!$E$48)^4*(1-E$4)^7+Drivers!$E$47*(1+Drivers!$E$48)^5*(1-E$4)^6+Drivers!$E$47*(1+Drivers!$E$48)^6*(1-E$4)^5+Drivers!$E$47*(1+Drivers!$E$48)^7*(1-E$4)^4+Drivers!$E$47*(1+Drivers!$E$48)^8*(1-E$4)^3+Drivers!$E$47*(1+Drivers!$E$48)^9*(1-E$4)^2+Drivers!$E$47*(1+Drivers!$E$48)^10*(1-E$4)^1+Drivers!$E$47*(1+Drivers!$E$48)^11*(1-E$4)^0)*Drivers!$B$29+(Drivers!$E$49*(1+Drivers!$E$50)^0*(1-Drivers!$B$14)^11+Drivers!$E$49*(1+Drivers!$E$50)^1*(1-Drivers!$B$14)^10+Drivers!$E$49*(1+Drivers!$E$50)^2*(1-Drivers!$B$14)^9+Drivers!$E$49*(1+Drivers!$E$50)^3*(1-Drivers!$B$14)^8+Drivers!$E$49*(1+Drivers!$E$50)^4*(1-Drivers!$B$14)^7+Drivers!$E$49*(1+Drivers!$E$50)^5*(1-Drivers!$B$14)^6+Drivers!$E$49*(1+Drivers!$E$50)^6*(1-Drivers!$B$14)^5+Drivers!$E$49*(1+Drivers!$E$50)^7*(1-Drivers!$B$14)^4+Drivers!$E$49*(1+Drivers!$E$50)^8*(1-Drivers!$B$14)^3+Drivers!$E$49*(1+Drivers!$E$50)^9*(1-Drivers!$B$14)^2+Drivers!$E$49*(1+Drivers!$E$50)^10*(1-Drivers!$B$14)^1+Drivers!$E$49*(1+Drivers!$E$50)^11*(1-Drivers!$B$14)^0)*Drivers!$B$28) | F7: =12*((Drivers!$E$47*(1+Drivers!$E$48)^0*(1-F$4)^11+Drivers!$E$47*(1+Drivers!$E$48)^1*(1-F$4)^10+Drivers!$E$47*(1+Drivers!$E$48)^2*(1-F$4)^9+Drivers!$E$47*(1+Drivers!$E$48)^3*(1-F$4)^8+Drivers!$E$47*(1+Drivers!$E$48)^4*(1-F$4)^7+Drivers!$E$47*(1+Drivers!$E$48)^5*(1-F$4)^6+Drivers!$E$47*(1+Drivers!$E$48)^6*(1-F$4)^5+Drivers!$E$47*(1+Drivers!$E$48)^7*(1-F$4)^4+Drivers!$E$47*(1+Drivers!$E$48)^8*(1-F$4)^3+Drivers!$E$47*(1+Drivers!$E$48)^9*(1-F$4)^2+Drivers!$E$47*(1+Drivers!$E$48)^10*(1-F$4)^1+Drivers!$E$47*(1+Drivers!$E$48)^11*(1-F$4)^0)*Drivers!$B$29+(Drivers!$E$49*(1+Drivers!$E$50)^0*(1-Drivers!$B$14)^11+Drivers!$E$49*(1+Drivers!$E$50)^1*(1-Drivers!$B$14)^10+Drivers!$E$49*(1+Drivers!$E$50)^2*(1-Drivers!$B$14)^9+Drivers!$E$49*(1+Drivers!$E$50)^3*(1-Drivers!$B$14)^8+Drivers!$E$49*(1+Drivers!$E$50)^4*(1-Drivers!$B$14)^7+Drivers!$E$49*(1+Drivers!$E$50)^5*(1-Drivers!$B$14)^6+Drivers!$E$49*(1+Drivers!$E$50)^6*(1-Drivers!$B$14)^5+Drivers!$E$49*(1+Drivers!$E$50)^7*(1-Drivers!$B$14)^4+Drivers!$E$49*(1+Drivers!$E$50)^8*(1-Drivers!$B$14)^3+Drivers!$E$49*(1+Drivers!$E$50)^9*(1-Drivers!$B$14)^2+Drivers!$E$49*(1+Drivers!$E$50)^10*(1-Drivers!$B$14)^1+Drivers!$E$49*(1+Drivers!$E$50)^11*(1-Drivers!$B$14)^0)*Drivers!$B$28) | G7: =12*((Drivers!$E$47*(1+Drivers!$E$48)^0*(1-G$4)^11+Drivers!$E$47*(1+Drivers!$E$48)^1*(1-G$4)^10+Drivers!$E$47*(1+Drivers!$E$48)^2*(1-G$4)^9+Drivers!$E$47*(1+Drivers!$E$48)^3*(1-G$4)^8+Drivers!$E$47*(1+Drivers!$E$48)^4*(1-G$4)^7+Drivers!$E$47*(1+Drivers!$E$48)^5*(1-G$4)^6+Drivers!$E$47*(1+Drivers!$E$48)^6*(1-G$4)^5+Drivers!$E$47*(1+Drivers!$E$48)^7*(1-G$4)^4+Drivers!$E$47*(1+Drivers!$E$48)^8*(1-G$4)^3+Drivers!$E$47*(1+Drivers!$E$48)^9*(1-G$4)^2+Drivers!$E$47*(1+Drivers!$E$48)^10*(1-G$4)^1+Drivers!$E$47*(1+Drivers!$E$48)^11*(1-G$4)^0)*Drivers!$B$29+(Drivers!$E$49*(1+Drivers!$E$50)^0*(1-Drivers!$B$14)^11+Drivers!$E$49*(1+Drivers!$E$50)^1*(1-Drivers!$B$14)^10+Drivers!$E$49*(1+Drivers!$E$50)^2*(1-Drivers!$B$14)^9+Drivers!$E$49*(1+Drivers!$E$50)^3*(1-Drivers!$B$14)^8+Drivers!$E$49*(1+Drivers!$E$50)^4*(1-Drivers!$B$14)^7+Drivers!$E$49*(1+Drivers!$E$50)^5*(1-Drivers!$B$14)^6+Drivers!$E$49*(1+Drivers!$E$50)^6*(1-Drivers!$B$14)^5+Drivers!$E$49*(1+Drivers!$E$50)^7*(1-Drivers!$B$14)^4+Drivers!$E$49*(1+Drivers!$E$50)^8*(1-Drivers!$B$14)^3+Drivers!$E$49*(1+Drivers!$E$50)^9*(1-Drivers!$B$14)^2+Drivers!$E$49*(1+Drivers!$E$50)^10*(1-Drivers!$B$14)^1+Drivers!$E$49*(1+Drivers!$E$50)^11*(1-Drivers!$B$14)^0)*Drivers!$B$28) | H7: =12*((Drivers!$E$47*(1+Drivers!$E$48)^0*(1-H$4)^11+Drivers!$E$47*(1+Drivers!$E$48)^1*(1-H$4)^10+Drivers!$E$47*(1+Drivers!$E$48)^2*(1-H$4)^9+Drivers!$E$47*(1+Drivers!$E$48)^3*(1-H$4)^8+Drivers!$E$47*(1+Drivers!$E$48)^4*(1-H$4)^7+Drivers!$E$47*(1+Drivers!$E$48)^5*(1-H$4)^6+Drivers!$E$47*(1+Drivers!$E$48)^6*(1-H$4)^5+Drivers!$E$47*(1+Drivers!$E$48)^7*(1-H$4)^4+Drivers!$E$47*(1+Drivers!$E$48)^8*(1-H$4)^3+Drivers!$E$47*(1+Drivers!$E$48)^9*(1-H$4)^2+Drivers!$E$47*(1+Drivers!$E$48)^10*(1-H$4)^1+Drivers!$E$47*(1+Drivers!$E$48)^11*(1-H$4)^0)*Drivers!$B$29+(Drivers!$E$49*(1+Drivers!$E$50)^0*(1-Drivers!$B$14)^11+Drivers!$E$49*(1+Drivers!$E$50)^1*(1-Drivers!$B$14)^10+Drivers!$E$49*(1+Drivers!$E$50)^2*(1-Drivers!$B$14)^9+Drivers!$E$49*(1+Drivers!$E$50)^3*(1-Drivers!$B$14)^8+Drivers!$E$49*(1+Drivers!$E$50)^4*(1-Drivers!$B$14)^7+Drivers!$E$49*(1+Drivers!$E$50)^5*(1-Drivers!$B$14)^6+Drivers!$E$49*(1+Drivers!$E$50)^6*(1-Drivers!$B$14)^5+Drivers!$E$49*(1+Drivers!$E$50)^7*(1-Drivers!$B$14)^4+Drivers!$E$49*(1+Drivers!$E$50)^8*(1-Drivers!$B$14)^3+Drivers!$E$49*(1+Drivers!$E$50)^9*(1-Drivers!$B$14)^2+Drivers!$E$49*(1+Drivers!$E$50)^10*(1-Drivers!$B$14)^1+Drivers!$E$49*(1+Drivers!$E$50)^11*(1-Drivers!$B$14)^0)*Drivers!$B$28)
A8: 0.7 | B8: =12*((Drivers!$E$47*(1+Drivers!$E$48)^0*(1-B$4)^11+Drivers!$E$47*(1+Drivers!$E$48)^1*(1-B$4)^10+Drivers!$E$47*(1+Drivers!$E$48)^2*(1-B$4)^9+Drivers!$E$47*(1+Drivers!$E$48)^3*(1-B$4)^8+Drivers!$E$47*(1+Drivers!$E$48)^4*(1-B$4)^7+Drivers!$E$47*(1+Drivers!$E$48)^5*(1-B$4)^6+Drivers!$E$47*(1+Drivers!$E$48)^6*(1-B$4)^5+Drivers!$E$47*(1+Drivers!$E$48)^7*(1-B$4)^4+Drivers!$E$47*(1+Drivers!$E$48)^8*(1-B$4)^3+Drivers!$E$47*(1+Drivers!$E$48)^9*(1-B$4)^2+Drivers!$E$47*(1+Drivers!$E$48)^10*(1-B$4)^1+Drivers!$E$47*(1+Drivers!$E$48)^11*(1-B$4)^0)*Drivers!$B$29+(Drivers!$E$49*(1+Drivers!$E$50)^0*(1-Drivers!$B$14)^11+Drivers!$E$49*(1+Drivers!$E$50)^1*(1-Drivers!$B$14)^10+Drivers!$E$49*(1+Drivers!$E$50)^2*(1-Drivers!$B$14)^9+Drivers!$E$49*(1+Drivers!$E$50)^3*(1-Drivers!$B$14)^8+Drivers!$E$49*(1+Drivers!$E$50)^4*(1-Drivers!$B$14)^7+Drivers!$E$49*(1+Drivers!$E$50)^5*(1-Drivers!$B$14)^6+Drivers!$E$49*(1+Drivers!$E$50)^6*(1-Drivers!$B$14)^5+Drivers!$E$49*(1+Drivers!$E$50)^7*(1-Drivers!$B$14)^4+Drivers!$E$49*(1+Drivers!$E$50)^8*(1-Drivers!$B$14)^3+Drivers!$E$49*(1+Drivers!$E$50)^9*(1-Drivers!$B$14)^2+Drivers!$E$49*(1+Drivers!$E$50)^10*(1-Drivers!$B$14)^1+Drivers!$E$49*(1+Drivers!$E$50)^11*(1-Drivers!$B$14)^0)*Drivers!$B$28) | C8: =12*((Drivers!$E$47*(1+Drivers!$E$48)^0*(1-C$4)^11+Drivers!$E$47*(1+Drivers!$E$48)^1*(1-C$4)^10+Drivers!$E$47*(1+Drivers!$E$48)^2*(1-C$4)^9+Drivers!$E$47*(1+Drivers!$E$48)^3*(1-C$4)^8+Drivers!$E$47*(1+Drivers!$E$48)^4*(1-C$4)^7+Drivers!$E$47*(1+Drivers!$E$48)^5*(1-C$4)^6+Drivers!$E$47*(1+Drivers!$E$48)^6*(1-C$4)^5+Drivers!$E$47*(1+Drivers!$E$48)^7*(1-C$4)^4+Drivers!$E$47*(1+Drivers!$E$48)^8*(1-C$4)^3+Drivers!$E$47*(1+Drivers!$E$48)^9*(1-C$4)^2+Drivers!$E$47*(1+Drivers!$E$48)^10*(1-C$4)^1+Drivers!$E$47*(1+Drivers!$E$48)^11*(1-C$4)^0)*Drivers!$B$29+(Drivers!$E$49*(1+Drivers!$E$50)^0*(1-Drivers!$B$14)^11+Drivers!$E$49*(1+Drivers!$E$50)^1*(1-Drivers!$B$14)^10+Drivers!$E$49*(1+Drivers!$E$50)^2*(1-Drivers!$B$14)^9+Drivers!$E$49*(1+Drivers!$E$50)^3*(1-Drivers!$B$14)^8+Drivers!$E$49*(1+Drivers!$E$50)^4*(1-Drivers!$B$14)^7+Drivers!$E$49*(1+Drivers!$E$50)^5*(1-Drivers!$B$14)^6+Drivers!$E$49*(1+Drivers!$E$50)^6*(1-Drivers!$B$14)^5+Drivers!$E$49*(1+Drivers!$E$50)^7*(1-Drivers!$B$14)^4+Drivers!$E$49*(1+Drivers!$E$50)^8*(1-Drivers!$B$14)^3+Drivers!$E$49*(1+Drivers!$E$50)^9*(1-Drivers!$B$14)^2+Drivers!$E$49*(1+Drivers!$E$50)^10*(1-Drivers!$B$14)^1+Drivers!$E$49*(1+Drivers!$E$50)^11*(1-Drivers!$B$14)^0)*Drivers!$B$28) | D8: =12*((Drivers!$E$47*(1+Drivers!$E$48)^0*(1-D$4)^11+Drivers!$E$47*(1+Drivers!$E$48)^1*(1-D$4)^10+Drivers!$E$47*(1+Drivers!$E$48)^2*(1-D$4)^9+Drivers!$E$47*(1+Drivers!$E$48)^3*(1-D$4)^8+Drivers!$E$47*(1+Drivers!$E$48)^4*(1-D$4)^7+Drivers!$E$47*(1+Drivers!$E$48)^5*(1-D$4)^6+Drivers!$E$47*(1+Drivers!$E$48)^6*(1-D$4)^5+Drivers!$E$47*(1+Drivers!$E$48)^7*(1-D$4)^4+Drivers!$E$47*(1+Drivers!$E$48)^8*(1-D$4)^3+Drivers!$E$47*(1+Drivers!$E$48)^9*(1-D$4)^2+Drivers!$E$47*(1+Drivers!$E$48)^10*(1-D$4)^1+Drivers!$E$47*(1+Drivers!$E$48)^11*(1-D$4)^0)*Drivers!$B$29+(Drivers!$E$49*(1+Drivers!$E$50)^0*(1-Drivers!$B$14)^11+Drivers!$E$49*(1+Drivers!$E$50)^1*(1-Drivers!$B$14)^10+Drivers!$E$49*(1+Drivers!$E$50)^2*(1-Drivers!$B$14)^9+Drivers!$E$49*(1+Drivers!$E$50)^3*(1-Drivers!$B$14)^8+Drivers!$E$49*(1+Drivers!$E$50)^4*(1-Drivers!$B$14)^7+Drivers!$E$49*(1+Drivers!$E$50)^5*(1-Drivers!$B$14)^6+Drivers!$E$49*(1+Drivers!$E$50)^6*(1-Drivers!$B$14)^5+Drivers!$E$49*(1+Drivers!$E$50)^7*(1-Drivers!$B$14)^4+Drivers!$E$49*(1+Drivers!$E$50)^8*(1-Drivers!$B$14)^3+Drivers!$E$49*(1+Drivers!$E$50)^9*(1-Drivers!$B$14)^2+Drivers!$E$49*(1+Drivers!$E$50)^10*(1-Drivers!$B$14)^1+Drivers!$E$49*(1+Drivers!$E$50)^11*(1-Drivers!$B$14)^0)*Drivers!$B$28) | E8: =12*((Drivers!$E$47*(1+Drivers!$E$48)^0*(1-E$4)^11+Drivers!$E$47*(1+Drivers!$E$48)^1*(1-E$4)^10+Drivers!$E$47*(1+Drivers!$E$48)^2*(1-E$4)^9+Drivers!$E$47*(1+Drivers!$E$48)^3*(1-E$4)^8+Drivers!$E$47*(1+Drivers!$E$48)^4*(1-E$4)^7+Drivers!$E$47*(1+Drivers!$E$48)^5*(1-E$4)^6+Drivers!$E$47*(1+Drivers!$E$48)^6*(1-E$4)^5+Drivers!$E$47*(1+Drivers!$E$48)^7*(1-E$4)^4+Drivers!$E$47*(1+Drivers!$E$48)^8*(1-E$4)^3+Drivers!$E$47*(1+Drivers!$E$48)^9*(1-E$4)^2+Drivers!$E$47*(1+Drivers!$E$48)^10*(1-E$4)^1+Drivers!$E$47*(1+Drivers!$E$48)^11*(1-E$4)^0)*Drivers!$B$29+(Drivers!$E$49*(1+Drivers!$E$50)^0*(1-Drivers!$B$14)^11+Drivers!$E$49*(1+Drivers!$E$50)^1*(1-Drivers!$B$14)^10+Drivers!$E$49*(1+Drivers!$E$50)^2*(1-Drivers!$B$14)^9+Drivers!$E$49*(1+Drivers!$E$50)^3*(1-Drivers!$B$14)^8+Drivers!$E$49*(1+Drivers!$E$50)^4*(1-Drivers!$B$14)^7+Drivers!$E$49*(1+Drivers!$E$50)^5*(1-Drivers!$B$14)^6+Drivers!$E$49*(1+Drivers!$E$50)^6*(1-Drivers!$B$14)^5+Drivers!$E$49*(1+Drivers!$E$50)^7*(1-Drivers!$B$14)^4+Drivers!$E$49*(1+Drivers!$E$50)^8*(1-Drivers!$B$14)^3+Drivers!$E$49*(1+Drivers!$E$50)^9*(1-Drivers!$B$14)^2+Drivers!$E$49*(1+Drivers!$E$50)^10*(1-Drivers!$B$14)^1+Drivers!$E$49*(1+Drivers!$E$50)^11*(1-Drivers!$B$14)^0)*Drivers!$B$28) | F8: =12*((Drivers!$E$47*(1+Drivers!$E$48)^0*(1-F$4)^11+Drivers!$E$47*(1+Drivers!$E$48)^1*(1-F$4)^10+Drivers!$E$47*(1+Drivers!$E$48)^2*(1-F$4)^9+Drivers!$E$47*(1+Drivers!$E$48)^3*(1-F$4)^8+Drivers!$E$47*(1+Drivers!$E$48)^4*(1-F$4)^7+Drivers!$E$47*(1+Drivers!$E$48)^5*(1-F$4)^6+Drivers!$E$47*(1+Drivers!$E$48)^6*(1-F$4)^5+Drivers!$E$47*(1+Drivers!$E$48)^7*(1-F$4)^4+Drivers!$E$47*(1+Drivers!$E$48)^8*(1-F$4)^3+Drivers!$E$47*(1+Drivers!$E$48)^9*(1-F$4)^2+Drivers!$E$47*(1+Drivers!$E$48)^10*(1-F$4)^1+Drivers!$E$47*(1+Drivers!$E$48)^11*(1-F$4)^0)*Drivers!$B$29+(Drivers!$E$49*(1+Drivers!$E$50)^0*(1-Drivers!$B$14)^11+Drivers!$E$49*(1+Drivers!$E$50)^1*(1-Drivers!$B$14)^10+Drivers!$E$49*(1+Drivers!$E$50)^2*(1-Drivers!$B$14)^9+Drivers!$E$49*(1+Drivers!$E$50)^3*(1-Drivers!$B$14)^8+Drivers!$E$49*(1+Drivers!$E$50)^4*(1-Drivers!$B$14)^7+Drivers!$E$49*(1+Drivers!$E$50)^5*(1-Drivers!$B$14)^6+Drivers!$E$49*(1+Drivers!$E$50)^6*(1-Drivers!$B$14)^5+Drivers!$E$49*(1+Drivers!$E$50)^7*(1-Drivers!$B$14)^4+Drivers!$E$49*(1+Drivers!$E$50)^8*(1-Drivers!$B$14)^3+Drivers!$E$49*(1+Drivers!$E$50)^9*(1-Drivers!$B$14)^2+Drivers!$E$49*(1+Drivers!$E$50)^10*(1-Drivers!$B$14)^1+Drivers!$E$49*(1+Drivers!$E$50)^11*(1-Drivers!$B$14)^0)*Drivers!$B$28) | G8: =12*((Drivers!$E$47*(1+Drivers!$E$48)^0*(1-G$4)^11+Drivers!$E$47*(1+Drivers!$E$48)^1*(1-G$4)^10+Drivers!$E$47*(1+Drivers!$E$48)^2*(1-G$4)^9+Drivers!$E$47*(1+Drivers!$E$48)^3*(1-G$4)^8+Drivers!$E$47*(1+Drivers!$E$48)^4*(1-G$4)^7+Drivers!$E$47*(1+Drivers!$E$48)^5*(1-G$4)^6+Drivers!$E$47*(1+Drivers!$E$48)^6*(1-G$4)^5+Drivers!$E$47*(1+Drivers!$E$48)^7*(1-G$4)^4+Drivers!$E$47*(1+Drivers!$E$48)^8*(1-G$4)^3+Drivers!$E$47*(1+Drivers!$E$48)^9*(1-G$4)^2+Drivers!$E$47*(1+Drivers!$E$48)^10*(1-G$4)^1+Drivers!$E$47*(1+Drivers!$E$48)^11*(1-G$4)^0)*Drivers!$B$29+(Drivers!$E$49*(1+Drivers!$E$50)^0*(1-Drivers!$B$14)^11+Drivers!$E$49*(1+Drivers!$E$50)^1*(1-Drivers!$B$14)^10+Drivers!$E$49*(1+Drivers!$E$50)^2*(1-Drivers!$B$14)^9+Drivers!$E$49*(1+Drivers!$E$50)^3*(1-Drivers!$B$14)^8+Drivers!$E$49*(1+Drivers!$E$50)^4*(1-Drivers!$B$14)^7+Drivers!$E$49*(1+Drivers!$E$50)^5*(1-Drivers!$B$14)^6+Drivers!$E$49*(1+Drivers!$E$50)^6*(1-Drivers!$B$14)^5+Drivers!$E$49*(1+Drivers!$E$50)^7*(1-Drivers!$B$14)^4+Drivers!$E$49*(1+Drivers!$E$50)^8*(1-Drivers!$B$14)^3+Drivers!$E$49*(1+Drivers!$E$50)^9*(1-Drivers!$B$14)^2+Drivers!$E$49*(1+Drivers!$E$50)^10*(1-Drivers!$B$14)^1+Drivers!$E$49*(1+Drivers!$E$50)^11*(1-Drivers!$B$14)^0)*Drivers!$B$28) | H8: =12*((Drivers!$E$47*(1+Drivers!$E$48)^0*(1-H$4)^11+Drivers!$E$47*(1+Drivers!$E$48)^1*(1-H$4)^10+Drivers!$E$47*(1+Drivers!$E$48)^2*(1-H$4)^9+Drivers!$E$47*(1+Drivers!$E$48)^3*(1-H$4)^8+Drivers!$E$47*(1+Drivers!$E$48)^4*(1-H$4)^7+Drivers!$E$47*(1+Drivers!$E$48)^5*(1-H$4)^6+Drivers!$E$47*(1+Drivers!$E$48)^6*(1-H$4)^5+Drivers!$E$47*(1+Drivers!$E$48)^7*(1-H$4)^4+Drivers!$E$47*(1+Drivers!$E$48)^8*(1-H$4)^3+Drivers!$E$47*(1+Drivers!$E$48)^9*(1-H$4)^2+Drivers!$E$47*(1+Drivers!$E$48)^10*(1-H$4)^1+Drivers!$E$47*(1+Drivers!$E$48)^11*(1-H$4)^0)*Drivers!$B$29+(Drivers!$E$49*(1+Drivers!$E$50)^0*(1-Drivers!$B$14)^11+Drivers!$E$49*(1+Drivers!$E$50)^1*(1-Drivers!$B$14)^10+Drivers!$E$49*(1+Drivers!$E$50)^2*(1-Drivers!$B$14)^9+Drivers!$E$49*(1+Drivers!$E$50)^3*(1-Drivers!$B$14)^8+Drivers!$E$49*(1+Drivers!$E$50)^4*(1-Drivers!$B$14)^7+Drivers!$E$49*(1+Drivers!$E$50)^5*(1-Drivers!$B$14)^6+Drivers!$E$49*(1+Drivers!$E$50)^6*(1-Drivers!$B$14)^5+Drivers!$E$49*(1+Drivers!$E$50)^7*(1-Drivers!$B$14)^4+Drivers!$E$49*(1+Drivers!$E$50)^8*(1-Drivers!$B$14)^3+Drivers!$E$49*(1+Drivers!$E$50)^9*(1-Drivers!$B$14)^2+Drivers!$E$49*(1+Drivers!$E$50)^10*(1-Drivers!$B$14)^1+Drivers!$E$49*(1+Drivers!$E$50)^11*(1-Drivers!$B$14)^0)*Drivers!$B$28)
